<bug id='2983' author='AlexTraan' open_date='2020-11-05T10:04:49Z' closed_time='2020-11-05T10:59:43Z'>
	<summary>[Ask] Error when call inference</summary>
	<description>
&lt;denchmark-h:h5&gt;System information (version)&lt;/denchmark-h&gt;


OpenVINO=&gt; ❔
Operating System / Platform =&gt; ❔
Compiler =&gt; ❔
Problem classification =&gt; ❔

&lt;denchmark-h:h5&gt;Detailed description&lt;/denchmark-h&gt;

Hi,
When i call "self._exec_net.infer(inputs={self._input_blob: frame})", i faced error:
"res = self._exec_net.infer(inputs={self._input_blob: frame})
File "ie_api.pyx", line 827, in openvino.inference_engine.ie_api.ExecutableNetwork.infer
File "ie_api.pyx", line 1117, in openvino.inference_engine.ie_api.InferRequest.infer
File "ie_api.pyx", line 1119, in openvino.inference_engine.ie_api.InferRequest.infer
File "ie_api.pyx", line 1265, in openvino.inference_engine.ie_api.InferRequest._fill_inputs
ValueError: could not broadcast input array from shape (1,3,229,229) into shape (1,3,299,299)"
i dont know why failed in here when two shape match, can anyone help me?
&lt;denchmark-h:h5&gt;Steps to reproduce&lt;/denchmark-h&gt;

&lt;denchmark-h:h5&gt;Issue submission checklist&lt;/denchmark-h&gt;


 I report the issue, it's not a question


 I checked the problem with documentation, FAQ, open issues, Stack Overflow, etc and have not found solution


 There is reproducer code and related data files: images, videos, models, etc.



	</description>
	<comments>
	</comments>
</bug>