<bug id='535' author='muupan' open_date='2019-08-25T04:00:22Z' closed_time='2019-08-30T03:12:14Z'>
	<summary>SARSA raises an error with GPU: ValueError: Unsupported dtype object</summary>
	<description>
tests/agents_tests/test_sarsa.py's slow gpu tests fail.
&lt;denchmark-code&gt;tests/agents_tests/test_sarsa.py::TestSARSAOnDiscreteABC::test_batch_training_gpu &lt;- tests/agents_tests/basetest_training.py FAILED

=============================================================================================================================== FAILURES ===============================================================================================================================
____________________________________________________________________________________________________________ TestSARSAOnDiscreteABC.test_batch_training_gpu ____________________________________________________________________________________________________________

self = &lt;test_sarsa.TestSARSAOnDiscreteABC testMethod=test_batch_training_gpu&gt;

    @testing.attr.slow
    @testing.attr.gpu
    def test_batch_training_gpu(self):
&gt;       self._test_batch_training(0, steps=100000)

tests/agents_tests/basetest_training.py:170:
_ _ _ _ _ _ _ _ _ _ _ _ _ _ _ _ _ _ _ _ _ _ _ _ _ _ _ _ _ _ _ _ _ _ _ _ _ _ _ _ _ _ _ _ _ _ _ _ _ _ _ _ _ _ _ _ _ _ _ _ _ _ _ _ _ _ _ _ _ _ _ _ _ _ _ _ _ _ _ _ _ _ _ _ _ _ _ _ _ _ _ _ _ _ _ _ _ _ _ _ _ _ _ _ _ _ _ _ _ _ _ _ _ _ _ _ _ _ _ _ _ _ _ _ _ _ _ _ _ _ _ _
tests/agents_tests/basetest_training.py:146: in _test_batch_training
    eval_env=test_env,
chainerrl/experiments/train_agent_batch.py:215: in train_agent_batch_with_evaluation
    logger=logger)
chainerrl/experiments/train_agent_batch.py:77: in train_agent_batch
    agent.batch_observe_and_train(obss, rs, dones, resets)
chainerrl/agents/dqn.py:512: in batch_observe_and_train
    self.replay_updater.update_if_necessary(self.t)
chainerrl/replay_buffer.py:289: in update_if_necessary
    self.update_func(transitions)
chainerrl/agents/dqn.py:269: in update
    loss = self._compute_loss(exp_batch, errors_out=errors_out)
chainerrl/agents/dqn.py:349: in _compute_loss
    y, t = self._compute_y_and_t(exp_batch)
chainerrl/agents/dqn.py:335: in _compute_y_and_t
    self._compute_target_values(exp_batch),
chainerrl/agents/sarsa.py:35: in _compute_target_values
    for i in range(len(exp_batch['action']))])
../.local/share/virtualenvs/chainerrl_20180827-9TPAa4mI/lib/python3.5/site-packages/cupy/creation/from_data.py:41: in array
    return core.array(obj, dtype, copy, order, subok, ndmin)
cupy/core/core.pyx:1714: in cupy.core.core.array
    ???
cupy/core/core.pyx:1791: in cupy.core.core.array
    ???
_ _ _ _ _ _ _ _ _ _ _ _ _ _ _ _ _ _ _ _ _ _ _ _ _ _ _ _ _ _ _ _ _ _ _ _ _ _ _ _ _ _ _ _ _ _ _ _ _ _ _ _ _ _ _ _ _ _ _ _ _ _ _ _ _ _ _ _ _ _ _ _ _ _ _ _ _ _ _ _ _ _ _ _ _ _ _ _ _ _ _ _ _ _ _ _ _ _ _ _ _ _ _ _ _ _ _ _ _ _ _ _ _ _ _ _ _ _ _ _ _ _ _ _ _ _ _ _ _ _ _ _

&gt;   ???
E   ValueError: Unsupported dtype object
&lt;/denchmark-code&gt;

This is because cupy.ndarray and python int are passed to cupy.array at the same time, which results in ValueError.
	</description>
	<comments>
	</comments>
</bug>