<bug id='1452' author='egrinstein' open_date='2020-04-22T18:55:14Z' closed_time='2020-04-25T00:57:17Z'>
	<summary>Can't use API/CLI to create task after update</summary>
	<description>
&lt;denchmark-h:h3&gt;My actions before raising this issue&lt;/denchmark-h&gt;


 Read/searched the docs
 Searched past issues

&lt;denchmark-h:h3&gt;Expected Behaviour&lt;/denchmark-h&gt;

I was able to use this query just fine before updating:
python cli.py --auth admin:rg!J957%12345 --debug --server-host 10.139.135.73 create --labels D:\data\Clips\labels.json task_name local D:\data\Clips\\frames.zip
&lt;denchmark-h:h3&gt;Current Behaviour&lt;/denchmark-h&gt;

I'm getting the following output:
send: b'POST /api/v1/tasks HTTP/1.1\r\nHost: 10.139.135.73:8080\r\nUser-Agent: python-requests/2.22.0\r\nAccept-Encoding: gzip, deflate\r\nAccept: */*\r\nConnection: keep-alive\r\nContent-Length: 89\r\nContent-Type: application/json\r\nAuthorization: Basic YWRtaW46cmchSjk1NyUxMjM0NQ==\r\n\r\n' send: b'{"name": "task_name", "labels": [{"name": "Zone0", "attributes": []}], "bug_tracker": ""}' reply: 'HTTP/1.1 400 Bad Request\r\n' header: Server: nginx/1.16.1 header: Date: Wed, 22 Apr 2020 18:49:01 GMT header: Content-Type: application/json header: Content-Length: 45 header: Connection: keep-alive header: Vary: Accept,Origin,Cookie header: X-Frame-Options: SAMEORIGIN header: Allow: GET, POST, HEAD, OPTIONS 400 Client Error: Bad Request for url: http://10.139.135.73:8080/api/v1/tasks
&lt;denchmark-h:h3&gt;Possible Solution&lt;/denchmark-h&gt;

If I checkout the master branch, I'm able to load the query just fine.
	</description>
	<comments>
	</comments>
</bug>