<bug id='171' author='jonashen' open_date='2018-07-11T00:31:18Z' closed_time='2018-10-09T16:18:28Z'>
	<summary>Can't run examples/theano/trpo_cartpole_pickled.py on Mac</summary>
	<description>
It was able to run when it was located at examples/trpo_cartpole_pickled.py.
Now, at examples/theano/trpo_cartpole_pickled.py, there is an unknown threading error.
	</description>
	<comments>
		<comment id='1' author='jonashen' date='2018-07-11T17:36:43Z'>
		Can you be more specific about the error?
		</comment>
		<comment id='2' author='jonashen' date='2018-07-11T17:54:57Z'>
		On mac, I get:
&lt;denchmark-code&gt;libc++abi.dylib: terminating with uncaught exception of type std::__1::system_error: thread::join failed: No such process
&lt;/denchmark-code&gt;

On linux, it starts to run but then the program stops outputting anything (sort of like if you're stuck in a while loop).
		</comment>
		<comment id='3' author='jonashen' date='2018-07-11T18:08:18Z'>
		Is there a backtrace?
		</comment>
		<comment id='4' author='jonashen' date='2018-07-11T18:44:19Z'>
		not sure what you mean
		</comment>
		<comment id='5' author='jonashen' date='2018-07-11T18:51:26Z'>
		e.g.
Traceback (most recent call last):
  File "/home/rjulian/miniconda2/envs/garage/lib/python3.5/multiprocessing/process.py", line 249, in _bootstrap
    self.run()
  File "/home/rjulian/miniconda2/envs/garage/lib/python3.5/multiprocessing/process.py", line 93, in run
    self._target(*self._args, **self._kwargs)
  File "/home/rjulian/miniconda2/envs/garage/lib/python3.5/multiprocessing/pool.py", line 108, in worker
    task = get()
  File "/home/rjulian/miniconda2/envs/garage/lib/python3.5/site-packages/joblib/pool.py", line 362, in get
    return recv()
  File "/home/rjulian/miniconda2/envs/garage/lib/python3.5/multiprocessing/connection.py", line 250, in recv
    buf = self._recv_bytes()
  File "/home/rjulian/miniconda2/envs/garage/lib/python3.5/multiprocessing/connection.py", line 407, in _recv_bytes
    buf = self._recv(4)
  File "/home/rjulian/miniconda2/envs/garage/lib/python3.5/multiprocessing/connection.py", line 379, in _recv
    chunk = read(handle, remaining)
		</comment>
		<comment id='6' author='jonashen' date='2018-07-11T18:53:43Z'>
		No, on mac I just get
&lt;denchmark-code&gt;2018-07-11 11:53:06.296841 PDT | [experiment_2018_07_11_11_53_00_0001] Populating workers...
libc++abi.dylib: terminating with uncaught exception of type std::__1::system_error: thread::join failed: No such process
libc++abi.dylib: terminating with uncaught exception of type std::__1::system_error: thread::join failed: No such process
libc++abi.dylib: terminating with uncaught exception of type std::__1::system_error: thread::join failed: No such process
...(repeating forever)
&lt;/denchmark-code&gt;

		</comment>
		<comment id='7' author='jonashen' date='2018-07-11T18:55:29Z'>
		Linux actually worked for me just now (the wait was just longer than expected). So this is now a Mac issue.
		</comment>
		<comment id='8' author='jonashen' date='2018-07-11T19:56:47Z'>
		This might be a joblib bug. Speculatively, someone might be calling .join() on a process which hasn't been spawned yet.
		</comment>
		<comment id='9' author='jonashen' date='2018-10-09T15:47:28Z'>
		&lt;denchmark-link:https://github.com/jonashen&gt;@jonashen&lt;/denchmark-link&gt;
 is this fixed?
		</comment>
		<comment id='10' author='jonashen' date='2018-10-09T16:18:28Z'>
		I reran it and it works. Closing now.
		</comment>
	</comments>
</bug>